<robot name="forklift">
    <origin xyz="0 0 0" rpy="0 0 0"/>
    <scale>1.2 1.2 1.2</scale>
    <namespace>/forklift</namespace>
    <static>true</static>

<material name="black">
    <color rgba="0.0 0.0 0.0 1.0"/>
</material>

<material name="dark">
  <color rgba="0.3 0.3 0.3 1.0"/>
</material>

<material name="light_black">
  <color rgba="0.4 0.4 0.4 1.0"/>
</material>

<material name="blue">
  <color rgba="0.0 0.0 0.8 1.0"/>
</material>

<material name="green">
  <color rgba="0.0 0.8 0.0 1.0"/>
</material>

<material name="grey">
  <color rgba="0.5 0.5 0.5 1.0"/>
</material>

<material name="orange">
  <color rgba="1.0 0.4235 0.0392 1.0"/>
</material>

<material name="brown">
  <color rgba="0.8706 0.8118 0.7647 1.0"/>
</material>

<material name="red">
  <color rgba="0.8 0.0 0.0 1.0"/>
</material>

<material name="white">
  <color rgba="1.0 1.0 1.0 1.0"/>
</material>

<link name="forklift_chassis">
    <visual>
      <origin xyz="0 0 0.0" rpy="0 0 0"/>
      <geometry>
        <mesh filename="package://myrobot/models/forklift/meshes/forklift_chassis.stl" scale="0.01 0.01 0.01"/>
      </geometry>
      <material name="orange"/>
    </visual>

    <collision>
      <geometry>
        <mesh filename="package://myrobot/models/forklift/meshes/forklift_chassis.stl" scale="0.01 0.01 0.01"/>
      </geometry>
    </collision>

    <inertial>
      <mass value="0.114" />
      <origin xyz="0 0 0" />
      <inertia ixx="0.001" ixy="0.0" ixz="0.0" iyy="0.001" iyz="0.0" izz="0.001" />
    </inertial>
  </link>

  <link name="left_wheel">
    <visual>
      <origin xyz="0 0 0.0" rpy="0 0 0"/>
      <geometry>
        <mesh filename="package://myrobot/models/forklift/meshes/forklift_left_wheel.stl" scale="0.01 0.01 0.01"/>
      </geometry>
      <material name="dark"/>
    </visual>

    <collision>
      <geometry>
        <mesh filename="package://myrobot/models/forklift/meshes/forklift_left_wheel.stl" scale="0.01 0.01 0.01"/>
      </geometry>
    </collision>

    <inertial>
      <mass value="0.114" />
      <origin xyz="0 0 0" />
      <inertia ixx="0.001" ixy="0.0" ixz="0.0" iyy="0.001" iyz="0.0" izz="0.001" />
    </inertial>
  </link>

  <link name="right_wheel">
    <visual>
      <origin xyz="0 0 0.0" rpy="0 0 0"/>
      <geometry>
        <mesh filename="package://myrobot/models/forklift/meshes/forklift_right_wheel.stl" scale="0.01 0.01 0.01"/>
      </geometry>
      <material name="dark"/>
    </visual>

    <collision>
      <geometry>
        <mesh filename="package://myrobot/models/forklift/meshes/forklift_right_wheel.stl" scale="0.01 0.01 0.01"/>
      </geometry>
    </collision>

    <inertial>
      <mass value="0.114" />
      <origin xyz="0 0 0" />
      <inertia ixx="0.001" ixy="0.0" ixz="0.0" iyy="0.001" iyz="0.0" izz="0.001" />
    </inertial>
  </link>

  <link name="back_wheel">
    <visual>
      <origin xyz="0 0 0.0" rpy="0 0 0"/>
      <geometry>
        <mesh filename="package://myrobot/models/forklift/meshes/forklift_back_wheel.stl" scale="0.01 0.01 0.01"/>
      </geometry>
      <material name="dark"/>
    </visual>

    <collision>
      <geometry>
        <mesh filename="package://myrobot/models/forklift/meshes/forklift_back_wheel.stl" scale="0.01 0.01 0.01"/>
      </geometry>
    </collision>

    <inertial>
      <mass value="0.114" />
      <origin xyz="0 0 0" />
      <inertia ixx="0.001" ixy="0.0" ixz="0.0" iyy="0.001" iyz="0.0" izz="0.001" />
    </inertial>
  </link>

  <joint name="right_wheel_joint" type="continuous">
    <origin xyz="0 0 0" />
    <axis xyz="1 0 0"/>
    <parent link="forklift_chassis"/>
    <child link="right_wheel"/>
  </joint>

  <joint name="left_wheel_joint" type="continuous">
    <origin xyz="0 0 0" />
    <axis xyz="1 0 0"/>
    <parent link="forklift_chassis"/>
    <child link="left_wheel"/>
  </joint>

  <joint name="back_wheel_joint" type="continuous">
    <origin xyz="0 0 0" />
    <axis xyz="1 0 0"/>
    <parent link="forklift_chassis"/>
    <child link="back_wheel"/>
  </joint>

</robot>