<?xml version='1.0'?>
<sdf version="1.4">
  <model name="forklift">
    <scale>1.2 1.2 1.2</scale>
    <pose>0 0 0 0 0 0</pose>
    <static>true</static>

    <!-- <link name="main_base"/> -->

    <link name="forklift_chassis">
      <pose>0 0 0   0 0 0</pose>
      <inertial>
        <mass>1.0</mass>
        <inertia>
          <ixx>100</ixx> 
          <ixy>0.0</ixy> 
          <ixz>0.0</ixz> 
          <iyy>100</iyy> 
          <iyz>0.0</iyz> 
          <izz>100</izz>
        </inertia>
      </inertial>
      <collision name="collision_forklift">
        <geometry>
          <mesh>
            <uri>model://forklift/meshes/forklift_chassis.stl</uri>
            <scale>0.01 0.01 0.01</scale>
          </mesh>
        </geometry>
      </collision>
      <visual name="forklift_visual">
        <pose>0 0 0 0 0 0</pose>
        <geometry>
          <mesh>
            <uri>model://forklift/meshes/forklift_chassis.stl</uri>
            <scale>0.01 0.01 0.01</scale>
          </mesh>
        </geometry>
      </visual>

    </link>

    <link name="left_wheel">
      <pose>0 0 0   0 0 0</pose>
      <inertial>
        <mass>1.0</mass>
        <inertia>
          <ixx>100</ixx> 
          <ixy>0.0</ixy> 
          <ixz>0.0</ixz> 
          <iyy>100</iyy> 
          <iyz>0.0</iyz> 
          <izz>100</izz>
        </inertia>
      </inertial>
      <collision name="collision_forkliftleft_wheel">
        <geometry>
          <mesh>
            <uri>model://forklift/meshes/forklift_left_wheel.stl</uri>
            <scale>0.01 0.01 0.01</scale>
          </mesh>
        </geometry>
      </collision>
      <visual name="forklift_visualleft_wheel">
        <pose>0 0 0 0 0 0</pose>
        <geometry>
          <mesh>
            <uri>model://forklift/meshes/forklift_left_wheel.stl</uri>
            <scale>0.01 0.01 0.01</scale>
          </mesh>
        </geometry>
      </visual>

    </link>


    <link name="right_wheel">
      <pose>0 0 0   0 0 0</pose>
      <inertial>
        <mass>1.0</mass>
        <inertia>
          <ixx>100</ixx> 
          <ixy>0.0</ixy> 
          <ixz>0.0</ixz> 
          <iyy>100</iyy> 
          <iyz>0.0</iyz> 
          <izz>100</izz>
        </inertia>
      </inertial>
      <collision name="collision_right_wheel">
        <geometry>
          <mesh>
            <uri>model://forklift/meshes/forklift_right_wheel.stl</uri>
            <scale>0.01 0.01 0.01</scale>
          </mesh>
        </geometry>
      </collision>
      <visual name="visual_right_wheel">
        <pose>0 0 0 0 0 0</pose>
        <geometry>
          <mesh>
            <uri>model://forklift/meshes/forklift_right_wheel.stl</uri>
            <scale>0.01 0.01 0.01</scale>
          </mesh>
        </geometry>
      </visual>

    </link>


    <link name="back_wheel">
      <pose>0 0 0   0 0 0</pose>
      <inertial>
        <mass>1.0</mass>
        <inertia>
          <ixx>100</ixx> 
          <ixy>0.0</ixy> 
          <ixz>0.0</ixz> 
          <iyy>100</iyy> 
          <iyz>0.0</iyz> 
          <izz>100</izz>
        </inertia>
      </inertial>
      <collision name="collision_back_wheel">
        <geometry>
          <mesh>
            <uri>model://forklift/meshes/forklift_back_wheel.stl</uri>
            <scale>0.01 0.01 0.01</scale>
          </mesh>
        </geometry>
      </collision>
      <visual name="collision_back_wheel">
        <pose>0 0 0 0 0 0</pose>
        <geometry>
          <mesh>
            <uri>model://forklift/meshes/forklift_back_wheel.stl</uri>
            <scale>0.01 0.01 0.01</scale>
          </mesh>
        </geometry>
      </visual>
    </link>

    <joint name="base_joint" type="fixed">
      <parent>main_base</parent>
      <child>forklift_chassis</child>
      <pose>0.0 0.0 0 0 0 0</pose>
    </joint>

    <joint name="left_wheel_joint" type="fixed">
      <parent>forklift_chassis</parent>
      <child>left_wheel</child>
      <pose>0.0 0.0 0 0 0 0</pose>
    </joint>

    <joint name="right_wheel_joint" type="revolute">
      <parent>forklift_chassis</parent>
      <child>right_wheel</child>
      <pose>0.0 0 0 0 0 0</pose>
      <axis>
        <xyz>0 0 1</xyz>
      </axis>
    </joint>

    <joint name="back_wheel_joint" type="revolute">
      <parent>forklift_chassis</parent>
      <child>back_wheel</child>
      <pose>0.0 0 0 0 0 0</pose>
      <axis>
        <xyz>0 0 1</xyz>
      </axis>
    </joint>

    <plugin name="forklift_diff_drive" filename="libgazebo_ros_diff_drive.so">

      <ros>
        <namespace>/forklift</namespace>
      </ros>

      <update_rate>30</update_rate>

      <!-- wheels -->
      <left_joint>left_wheel_joint</left_joint>
      <right_joint>right_wheel_joint</right_joint>

      <!-- kinematics -->
      <wheel_separation>0.160</wheel_separation>
      <wheel_diameter>0.066</wheel_diameter>

      <!-- limits -->
      <max_wheel_torque>20</max_wheel_torque>
      <max_wheel_acceleration>1.0</max_wheel_acceleration>

      <command_topic>cmd_vel</command_topic>

      <!-- output -->
      <publish_odom>true</publish_odom>
      <publish_odom_tf>true</publish_odom_tf>
      <publish_wheel_tf>false</publish_wheel_tf>

      <odometry_topic>odom</odometry_topic>
      <odometry_frame>odom</odometry_frame>
      <robot_base_frame>forklift_chassis</robot_base_frame>

    </plugin>

    <plugin name="forklift_joint_state" filename="libgazebo_ros_joint_state_publisher.so">
      <ros>
        <namespace>/forklift</namespace>
        <remapping>~/out:=joint_states</remapping>
      </ros>
      <update_rate>30</update_rate>
      <joint_name>left_wheel_joint</joint_name>
      <joint_name>right_wheel_joint</joint_name>
    </plugin>      

  </model>
</sdf>
